-------------------------
2018/12/26 17:05:23
信息:ExceptionError_Logger
成员名: Boolean TestCacheToken()
异常信息: Exception Test
引发异常的程序集或对象: Token
栈：   在 Token.Controllers.TokenController.TestCacheToken() 位置 C:\Users\Project\WebApi\Token\Controllers\TokenController.cs:行号 64
   在 lambda_method(Closure , Object , Object[] )
   在 System.Web.Http.Controllers.ReflectedHttpActionDescriptor.ActionExecutor.<>c__DisplayClass6_2.<GetExecutor>b__2(Object instance, Object[] methodParameters)
   在 System.Web.Http.Controllers.ReflectedHttpActionDescriptor.ActionExecutor.Execute(Object instance, Object[] arguments)
   在 System.Web.Http.Controllers.ReflectedHttpActionDescriptor.ExecuteAsync(HttpControllerContext controllerContext, IDictionary`2 arguments, CancellationToken cancellationToken)
--- 引发异常的上一位置中堆栈跟踪的末尾 ---
   在 System.Runtime.CompilerServices.TaskAwaiter.ThrowForNonSuccess(Task task)
   在 System.Runtime.CompilerServices.TaskAwaiter.HandleNonSuccessAndDebuggerNotification(Task task)
   在 System.Web.Http.Controllers.ApiControllerActionInvoker.<InvokeActionAsyncCore>d__1.MoveNext()
--- 引发异常的上一位置中堆栈跟踪的末尾 ---
   在 System.Runtime.CompilerServices.TaskAwaiter.ThrowForNonSuccess(Task task)
   在 System.Runtime.CompilerServices.TaskAwaiter.HandleNonSuccessAndDebuggerNotification(Task task)
   在 System.Web.Http.Controllers.ActionFilterResult.<ExecuteAsync>d__5.MoveNext()
--- 引发异常的上一位置中堆栈跟踪的末尾 ---
   在 System.Runtime.CompilerServices.TaskAwaiter.ThrowForNonSuccess(Task task)
   在 System.Runtime.CompilerServices.TaskAwaiter.HandleNonSuccessAndDebuggerNotification(Task task)
   在 System.Web.Http.Filters.AuthorizationFilterAttribute.<ExecuteAuthorizationFilterAsyncCore>d__3.MoveNext()
--- 引发异常的上一位置中堆栈跟踪的末尾 ---
   在 System.Runtime.CompilerServices.TaskAwaiter.ThrowForNonSuccess(Task task)
   在 System.Runtime.CompilerServices.TaskAwaiter.HandleNonSuccessAndDebuggerNotification(Task task)
   在 System.Web.Http.Dispatcher.HttpControllerDispatcher.<SendAsync>d__15.MoveNext()
